Workbook

Sheet Cover
B2: Brookfield India Real Estate Trust (BIRET)
B4: Business Analysis & Valuation – Complete DCF Model
B6: Equity research valuation · Built on the asset-wise revenue engine of the user's model · Valuation date 10 October 2026 · Rs crore unless stated
B10: Sheet index (click to navigate)
B11: Sheet | C11: Purpose
B12: Summary | C12: Target price, football field, key financials, checks status
B13: Inputs | C13: Market data, pro-forma net-debt bridge, global assumptions with sources
B14: Hist_Quality | C14: Historical analysis, cash-flow quality, Du Pont, normalisations
B15: Rev_Build | C15: Asset-wise leasing engine rebuilt live from the user's Revenue Estimation
B16: Fin_Proj | C16: Income statement, debt schedule, capex, NDCF and DPU, FY27E–FY36E
B17: WACC | C17: CAPM (INR Rf, CRP, bottom-up beta), cost of debt, synthetic rating, WACC
B18: DCF_FCFF | C18: FCFF DCF, terminal value, EV-to-unit bridge, sensitivities, reverse DCF, value of growth
B19: DDM_NDCF | C19: Dividend discount / NDCF model at cost of equity
B20: Relative | C20: Peer REIT P/NAV, EV/NOI, distribution yield
B21: NAV_Asset | C21: Asset-by-asset NAV: going concern, cap-rate range, stress/liquidation, replacement cost
B22: EVA | C22: EVA, ROIC vs WACC, EVA↔DCF reconciliation, value-enhancement levers, capital structure
... B26: Checks | C26: Reconciliation to user's model and integrity tests
B28: Colour legend
B29: Green = assumption behind a forecast (the cells to change)
B30: Blue = forecast value calculated by the model (FY27E onward)
B31: Black = historical and market data, formulas, labels
B32: No fills or other colours are used; key outputs are bold and boxed
B34: Methodology notes and limitations
B35: 1. Not applicable to this asset: private-company valuation and start-up valuation (Sessions 14–16) – BIRET is a listed, stabilised REIT. The JV-stake illiquidity discount applies the private-asset concept.
B36: 2. Revenue FY27E–FY29E reproduces the user's engine exactly (see Checks); FY30E–FY36E fade at 5% growth. Interest defaults to a debt schedule – switch to the user's coverage-ratio method on Inputs.
B37: 3. Market data (price, units, G-sec, peers) were gathered from public sources on 8–10 Oct 2026; Brookfield's own PDFs could not be opened, so some company figures come from secondary summaries – verify before external use.
B38: 4. Net debt for Mindspace and KRT is derived from reported LTV; partner share of value, cap rates, development cost and the NDCF calibration are analyst assumptions flagged on the sheets.
B39: 5. Valuation outputs are model estimates for coursework/research purposes, not investment advice.

Sheet Summary
B1: BROOKFIELD INDIA REAL ESTATE TRUST (NSE: BIRET) – VALUATION SUMMARY
B2: Equity research DCF built on the user's asset-wise revenue model · Valuation date 10-Oct-2026 · Rs per unit unless stated
B4: 1. Valuation and recommendation | K4: 2. Key assumptions & market snapshot
B5: Method | C5: Value / unit (Rs) | D5: Weight | E5: Contribution | F5: vs CMP | K5: Current price (Rs) | L5: =Inputs!$C$10 -> 328.8
B6: FCFF DCF (WACC, Gordon TV) | C6: =DCF_FCFF!$C$61 -> 331.89843 | D6: =Inputs!$C$63 -> 0.3 | E6: =C6*D6 -> 99.56953 | F6: =C6/Inputs!$C$10-1 -> 0.0094234631 | K6: Market cap (Rs cr) | L6: =Inputs!$C$12 -> 27286.483
B7: NDCF dividend discount model | C7: =DDM_NDCF!$C$18 -> 387.85402 | D7: =Inputs!$C$64 -> 0.2 | E7: =C7*D7 -> 77.570804 | F7: =C7/Inputs!$C$10-1 -> 0.17960468 | K7: Units (crore) | L7: =Inputs!$C$11 -> 82.988087
B8: NAV – asset-based (cap-rate) | C8: =NAV_Asset!$G$33 -> 317.66065 | D8: =Inputs!$C$65 -> 0.25 | E8: =C8*D8 -> 79.415164 | F8: =C8/Inputs!$C$10-1 -> -0.03387879 | K8: Pro-forma net debt (Rs cr) | L8: =Inputs!$C$34 -> 14060.565
B9: Relative – peer REIT multiples | C9: =Relative!$D$24 -> 363.55931 | D9: =Inputs!$C$66 -> 0.25 | E9: =C9*D9 -> 90.889826 | F9: =C9/Inputs!$C$10-1 -> 0.10571565 | K9: Risk-free (INR, Damodaran) | L9: =WACC!$C$8 -> 0.0536
B10: Blended intrinsic value | D10: =SUM(D6:D9) -> 1 | E10: =SUM(E6:E9) -> 347.44532 | K10: Cost of equity | L10: =WACC!$C$26 -> 0.10727921
B11: + Real-option value (after haircut) | E11: =Real_Options!$C$42 -> 5.665419 | K11: WACC | L11: =WACC!$C$44 -> 0.090397496
B12: TARGET PRICE (Rs per unit) | E12: =E10+E11 -> 353.11074 | K12: Terminal growth | L12: =DCF_FCFF!C26 -> 0.04
B13: Current market price (Rs) | E13: =Inputs!$C$10 -> 328.8 | K13: Market-implied WACC (reverse DCF) | L13: =DCF_FCFF!$C$106 -> 0.090834012
B14: Upside / (downside) | E14: =E12/E13-1 -> 0.073937783 | K14: DCF EV (Rs cr, 100% consolidated) | L14: =DCF_FCFF!C43 -> 44624.773
B15: Rating | E15: =IF(E14>Inputs!$C$69,"BUY",IF(E14<Inputs!$C$70,"SELL","HOLD")) -> HOLD | K15: Implied EV / NOI FY28E | L15: =DCF_FCFF!C66 -> 13.896105
B16: Probability-weighted scenario value (Rs) | E16: =Scenario_DT!$U$21 -> 336.87227 | K16: Implied exit cap rate | L16: =DCF_FCFF!C37 -> 0.073205783
B17: Monte Carlo mean / P(value > price) | E17: =Monte_Carlo!$C$13 -> 342.99344 | F17: =Monte_Carlo!$C$22 -> 0.548 | K17: Distribution yield (annualised Q1) | L17: =Relative!N16 -> 0.068126521
B18: Reported NAV per unit (Mar-26) / pro-forma post-QIP | E18: =Inputs!$C$13 -> 386.66 | F18: =NAV_Asset!$G$34 -> 379.85862 | K18: P / NAV (pro-forma) | L18: =Relative!M16 -> 0.8655852
B19: Model integrity | E19: =Checks!$F$29 -> ALL PASS | K19: Partners' share of value | L19: =Rev_Build!$D$75 -> 0.20341657
B22: 3. Key financials (Rs crore)
C23: FY25A | D23: FY26A | E23: FY27E | F23: FY28E | G23: FY29E | H23: FY31E | I23: FY36E
B24: Revenue | C24: =Fin_Proj!G24 -> 2385.592 | D24: =Fin_Proj!H24 -> 2962.259 | E24: =Fin_Proj!I24 -> 3936.7405 | F24: =Fin_Proj!J24 -> 4143.6326 | G24: =Fin_Proj!K24 -> 4352.1901 | H24: =Fin_Proj!M24 -> 4798.2896 | I24: =Fin_Proj!R24 -> 6123.9685
B25: EBITDA | C25: =Fin_Proj!G29 -> 1729.884 | D25: =Fin_Proj!H29 -> 2136.3393 | E25: =Fin_Proj!I29 -> 2776.0209 | F25: =Fin_Proj!J29 -> 3005.6346 | G25: =Fin_Proj!K29 -> 3200.1394 | H25: =Fin_Proj!M29 -> 3528.1537 | I25: =Fin_Proj!R29 -> 4502.9175
B26: EBITDA margin | C26: =Fin_Proj!G30 -> 0.72513823 | D26: =Fin_Proj!H30 -> 0.72118586 | E26: =Fin_Proj!I30 -> 0.70515719 | F26: =Fin_Proj!J30 -> 0.72536224 | G26: =Fin_Proj!K30 -> 0.73529403 | H26: =Fin_Proj!M30 -> 0.73529403 | I26: =Fin_Proj!R30 -> 0.73529403
B27: Net profit to unitholders | C27: =Fin_Proj!G40 -> 188.64397 | D27: =Fin_Proj!H40 -> 474.87129 | E27: =Fin_Proj!I40 -> 833.16758 | F27: =Fin_Proj!J40 -> 966.52523 | G27: =Fin_Proj!K40 -> 1067.7065 | H27: =Fin_Proj!M40 -> 1309.3662 | I27: =Fin_Proj!R40 -> 2021.9834
B28: Distribution per unit (Rs) | E28: =Fin_Proj!I86 -> 22.6 | F28: =Fin_Proj!J86 -> 24.586689 | G28: =Fin_Proj!K86 -> 25.886529 | H28: =Fin_Proj!M86 -> 28.248721 | I28: =Fin_Proj!R86 -> 35.615167
B29: Interest cover (EBITDA/interest) | E29: =Fin_Proj!I59 -> 2.4869879 | F29: =Fin_Proj!J59 -> 2.6218972 | G29: =Fin_Proj!K59 -> 2.7144282 | H29: =Fin_Proj!M59 -> 2.9310085 | I29: =Fin_Proj!R59 -> 3.6277757
B30: FCFF | E30: =DCF_FCFF!I17 -> 1933.1939 | F30: =DCF_FCFF!J17 -> 1831.9088 | G30: =DCF_FCFF!K17 -> 2096.4935 | H30: =DCF_FCFF!M17 -> 2621.6774 | I30: =DCF_FCFF!R17 -> 3341.3263
B31: ROIC on book capital | E31: =EVA!I19 -> 0.053768039 | F31: =EVA!J19 -> 0.058888045 | G31: =EVA!K19 -> 0.062500669 | H31: =EVA!M19 -> 0.072328281 | I31: =EVA!R19 -> 0.10341702
B33: 4. Football field – value per unit (Rs)
B34: Method | C34: Low | D34: Spread | E34: High | F34: Point
B35: DCF (WACC ±0.5pp, g ±0.5pp) | C35: =MIN(MIN(DCF_FCFF!D77:F79),MAX(DCF_FCFF!D77:F79)) -> 273.21523 | D35: =E35-C35 -> 145.75039 | E35: =MAX(MIN(DCF_FCFF!D77:F79),MAX(DCF_FCFF!D77:F79)) -> 418.96562 | F35: =DCF_FCFF!$C$61 -> 331.89843
B36: DDM (CoE ±0.5pp, g ±0.5pp) | C36: =MIN(MIN(DDM_NDCF!D28:F30),MAX(DDM_NDCF!D28:F30)) -> 348.93581 | D36: =E36-C36 -> 90.97425 | E36: =MAX(MIN(DDM_NDCF!D28:F30),MAX(DDM_NDCF!D28:F30)) -> 439.91006 | F36: =DDM_NDCF!$C$18 -> 387.85402
B37: NAV (cap rate ±25bp) | C37: =MIN(NAV_Asset!$I$33,NAV_Asset!$H$33) -> 302.93275 | D37: =E37-C37 -> 30.466933 | E37: =MAX(NAV_Asset!$I$33,NAV_Asset!$H$33) -> 333.39968 | F37: =NAV_Asset!$G$33 -> 317.66065
B38: Relative (peer min–max) | C38: =MIN(Relative!$C$24,Relative!$E$24) -> 340.40995 | D38: =E38-C38 -> 42.314658 | E38: =MAX(Relative!$C$24,Relative!$E$24) -> 382.72461 | F38: =Relative!$D$24 -> 363.55931
B39: Scenarios (bear – bull) | C39: =MIN(Scenario_DT!$U$6,Scenario_DT!$U$8) -> 223.18443 | D39: =E39-C39 -> 237.32336 | E39: =MAX(Scenario_DT!$U$6,Scenario_DT!$U$8) -> 460.50779 | F39: =Scenario_DT!$U$21 -> 336.87227
B40: Monte Carlo (P10 – P90) | C40: =MIN(Monte_Carlo!$C$17,Monte_Carlo!$C$20) -> 266.63161 | D40: =E40-C40 -> 162.10283 | E40: =MAX(Monte_Carlo!$C$17,Monte_Carlo!$C$20) -> 428.73443 | F40: =Monte_Carlo!$C$13 -> 342.99344
B41: 52-week trading range | C41: =MIN(Inputs!$C$15,Inputs!$C$14) -> 311.26 | D41: =E41-C41 -> 65.24 | E41: =MAX(Inputs!$C$15,Inputs!$C$14) -> 376.5 | F41: =Inputs!$C$10 -> 328.8
B62: Notes: (1) FCFF DCF is on 100% consolidated cash flows, bridged to unitholders after net debt, partners' share and the NCP JV. (2) Real options are shown separately and haircut. (3) All inputs, sources and assumptions are on the Inputs and method sheets (green cells).

Sheet Inputs
B1: INPUTS – market data, balance-sheet bridge and global assumptions
B2: Green = assumption behind a forecast · Blue = forecast value calculated by the model · Black = everything else · Rs crore unless stated
B5: A. Market data & valuation date
B6: Item | C6: Value | D6: Unit | E6: Source / note
B7: Valuation date | C7: 46305 | D7: date | E7: Date of this analysis
B8: FY27 year-end | C8: 46477 | D8: date | E8: Indian fiscal year ends 31 March
B9: Fraction of FY27 remaining after valuation date | C9: =($C$8-$C$7)/365 -> 0.47123288 | D9: years | E9: Used for stub-period cash flow and mid-period discounting
B10: Current market price (Rs/unit) | C10: 328.8 | D10: Rs | E10: NSE close 8-Oct-2026 (Kotak Neo / Tickertape quotes: Rs 328.8–330.3)
B11: Units outstanding | C11: 82.988087 | D11: crore | E11: 829,880,869 units post April-2026 QIP (Q1 FY27 distribution Rs 464.73 cr / DPU Rs 5.60 cross-checks)
B12: Market capitalisation | C12: =$C$10*$C$11 -> 27286.483 | D12: Rs cr
B13: Reported NAV per unit (31-Mar-2026) | C13: 386.66 | D13: Rs | E13: Brookfield India REIT Annual Report FY26 (consolidated NAV at fair value)
B14: 52-week high | C14: 376.5 | D14: Rs | E14: Kotak Neo, 8-Oct-2026
B15: 52-week low | C15: 311.26 | D15: Rs | E15: Kotak Neo, 8-Oct-2026
B16: Q1 FY27 DPU (declared Aug-2026) | C16: 5.6 | D16: Rs | E16: Q1 FY27 press release; record date 13-Aug-2026
B17: Annualised DPU (Q1 x 4) | C17: =$C$16*4 -> 22.4 | D17: Rs
B18: FY26 DPU | C18: 21.4 | D18: Rs | E18: FY26 results (incl. Rs 5.50 for Q4)
B19: April-2026 QIP issue price | C19: 323 | D19: Rs | E19: Institutional placement closed 21-Apr-2026
B21: B. Capital structure & pro-forma net debt bridge (consolidated)
B22: Item | C22: Value | D22: Unit | E22: Source / note
B23: Borrowings incl. accrued interest, 31-Mar-2026 | C23: 16432.783 | D23: Rs cr | E23: FY26 Annual Report (Rs 164,327.82 mn)
B24: Cash & equivalents, 31-Mar-2026 | C24: 674.218 | D24: Rs cr | E24: FY26 Annual Report (Rs 6,742.18 mn)
B25: Ecoworld Tranche-2 deferred consideration | C25: 1125 | D25: Rs cr | E25: Q4 FY26 investor update (counted in LTV); settled from 360 ONE proceeds
B26: April-2026 QIP gross proceeds | C26: 2600 | D26: Rs cr | E26: Rs 26 bn raised at Rs 323/unit (~8.05 cr units); used to repay debt
B27: QIP issue costs (% of proceeds) | C27: 0.02 | D27: % | E27: ASSUMPTION – typical placement cost 1.5–2.5%
B28: QIP net proceeds applied to debt | C28: =$C$26*(1-$C$27) -> 2548 | D28: Rs cr
B29: 360 ONE primary investment in Ecoworld SPV | C29: 1125 | D29: Rs cr | E29: 22-Apr-2026: ~13% stake for Rs 1,125 cr; settles Tranche-2 liability
B30: BKC (GBKC) acquisition – enterprise value, 100% | C30: 1700 | D30: Rs cr | E30: Announced 10-Aug-2026; closed 29-Sep-2026 as 50:50 JV with NCW/Nuvama
B31: REIT share of BKC JV | C31: 0.5 | D31: % | E31: Press release
B32: REIT funding of BKC stake (assumed debt-funded) | C32: =$C$30*$C$31 -> 850 | D32: Rs cr | E32: ASSUMPTION – funded by debt/cash; value-neutral in the bridge (asset added back at cost)
B33: Pro-forma gross debt | C33: =$C$23-$C$28+$C$32 -> 14734.783 | D33: Rs cr | E33: Mar-26 borrowings less QIP repayment plus BKC funding
B34: Pro-forma consolidated net debt | C34: =$C$33-$C$24+$C$25-$C$29 -> 14060.565 | D34: Rs cr | E34: Tranche-2 liability and 360 ONE cash offset; cross-check: mgmt pro-forma net debt Rs 15,363 cr incl. NCP share
B35: North Commercial Portfolio gross debt (100%) | C35: 3400 | D35: Rs cr | E35: User model 'Operational Metrics'!Y55 (Rs 34 bn, Q4 FY26)
B36: REIT share of North Commercial Portfolio (NCP) | C36: 0.5 | D36: % | E36: Equity-accounted JV (Worldmark Delhi/Gurugram, Airtel Center, Pavilion Mall)
B37: Illiquidity / non-control discount on JV stakes (BAV: private-asset adjustment) | C37: 0.1 | D37: % | E37: ASSUMPTION – Damodaran range 10–30% for illiquid stakes; low end used (JV is joint-controlled)
B38: Memo: minority interest, book value FY25 | C38: 1980.695 | D38: Rs cr | E38: User model 'Balance Sheet'!F13
B40: C. Operating & capex assumptions
B41: Item | C41: Value | D41: Unit | E41: Source / note
B42: Statutory SPV tax rate (new regime, 22% + surcharge + cess) | C42: 0.2517 | D42: % | E42: Income-tax rate; user model uses 24–26% effective on PBT
B43: Maintenance capex (Rs per sq ft per month, on operating area) | C43: 2 | D43: Rs | E43: Valuer assumption in Brookfield valuation report (Rs 2 psf/month)
B44: Maintenance capex inflation | C44: 0.045 | D44: % | E44: ASSUMPTION – ~RBI CPI
...

Sheet Hist_Quality
B1: HISTORICAL ANALYSIS & ACCOUNTING QUALITY – what to trust, what to normalise
B2: FY22–FY25 balance sheet and cash flow from user model (Ace Equity extracts) · FY26 P&L from 'Quarterly-data' · FY26 balance sheet from FY26 annual report (partial)
B4: Rs crore | C4: Unit | D4: FY22A | E4: FY23A | F4: FY24A | G4: FY25A | H4: FY26A
B5: A. Reported performance
B6: Revenue from operations | C6: Rs cr | D6: =Fin_Proj!D24 -> 876.791 | E6: =Fin_Proj!E24 -> 1196.999 | F6: =Fin_Proj!F24 -> 1780.481 | G6: =Fin_Proj!G24 -> 2385.592 | H6: =Fin_Proj!H24 -> 2962.259
B7: growth | C7: % | E7: =Fin_Proj!E25 -> 0.36520448 | F7: =Fin_Proj!F25 -> 0.48745404 | G7: =Fin_Proj!G25 -> 0.33985816 | H7: =Fin_Proj!H25 -> 0.2417291 | I7: FY26 includes Ecoworld from Dec-2025 and a full year of the NCP/G1/Powai step-ups – not organic
B8: EBITDA | C8: Rs cr | D8: =Fin_Proj!D29 -> 618.31094 | E8: =Fin_Proj!E29 -> 815.55074 | F8: =Fin_Proj!F29 -> 1254.6933 | G8: =Fin_Proj!G29 -> 1729.884 | H8: =Fin_Proj!H29 -> 2136.3393
B9: EBITDA margin | C9: % | D9: =Fin_Proj!D30 -> 0.70519763 | E9: =Fin_Proj!E30 -> 0.68132951 | F9: =Fin_Proj!F30 -> 0.70469344 | G9: =Fin_Proj!G30 -> 0.72513823 | H9: =Fin_Proj!H30 -> 0.72118586
B10: Net profit to unitholders | C10: Rs cr | D10: =Fin_Proj!D40 -> 246.27394 | E10: =Fin_Proj!E40 -> 131.21374 | F10: =Fin_Proj!F40 -> 20.732279 | G10: =Fin_Proj!G40 -> 188.64397 | H10: =Fin_Proj!H40 -> 474.87129
B11: net margin | C11: % | D11: =D10/D6 -> 0.28088101 | E11: =E10/E6 -> 0.10961892 | F11: =F10/F6 -> 0.011644201 | G11: =G10/G6 -> 0.079076375 | H11: =H10/H6 -> 0.16030715
B12: Interest expense | C12: Rs cr | D12: =Fin_Proj!D34 -> 208.069 | E12: =Fin_Proj!E34 -> 432.457 | F12: =Fin_Proj!F34 -> 852.199 | G12: =Fin_Proj!G34 -> 1078.177 | H12: =Fin_Proj!H34 -> 974.78
B13: B. Balance sheet (FY26: partial)
B14: Shareholders' funds (book equity) | C14: Rs cr | D14: 8882.093 | E14: 8333.738 | F14: 10124.159 | G14: 14029.92 | I14: 'Balance Sheet' row 12
B15: Minority interest | C15: Rs cr | D15: 0 | E15: 0 | F15: 2005.5 | G15: 1980.695 | I15: 'Balance Sheet' row 13
B16: Total debt | C16: Rs cr | D16: 5165.534 | E16: 5452.038 | F16: 12056.296 | G16: 9058.525 | H16: =Inputs!$C$23 -> 16432.783 | I16: FY26: borrowings incl. accrued interest, annual report
B17: Cash & bank | C17: Rs cr | D17: 255.014 | E17: 258.019 | F17: 517.403 | G17: 665.744 | H17: =Inputs!$C$24 -> 674.218
B18: Total assets | C18: Rs cr | D18: 14410.252 | E18: 14271.619 | F18: 25076.145 | G18: 26196.848
B19: Net debt | C19: Rs cr | D19: =D16-D17 -> 4910.52 | E19: =E16-E17 -> 5194.019 | F19: =F16-F17 -> 11538.893 | G19: =G16-G17 -> 8392.781 | H19: =H16-H17 -> 15758.565
B21: C. Cash-flow quality (is profit backed by cash?)
B22: Cash from operations | C22: Rs cr | D22: 605.92 | E22: 953.117 | F22: 1282.101 | G22: 1847.952 | I22: 'Cash Flow' row 45
B23: Tax paid per cash-flow statement | C23: Rs cr | D23: -17.485 | E23: 25.863 | F23: 25.612 | G23: -8.096 | I23: Sign convention in the extract is inconsistent; magnitude used
B24: Purchase of fixed assets | C24: Rs cr | D24: -4.242 | E24: -5.37 | F24: -18.166 | G24: -1.296 | I24: Investment property additions sit in 'investment in subsidiaries' for acquisitions
B25: CFO / EBITDA | C25: x | D25: =D22/D8 -> 0.97996002 | E25: =E22/E8 -> 1.168679 | F25: =F22/F8 -> 1.0218442 | G25: =G22/G8 -> 1.068252 | I25: Below 1.0 because interest is deducted inside CFO (Ind-AS 7 presentation)
B26: CFO / net profit | C26: x | D26: =D22/D10 -> 2.4603496 | E26: =E22/E10 -> 7.2638504 | F26: =F22/F10 -> 61.840814 | G26: =G22/G10 -> 9.7959772 | I26: Very high: depreciation Rs 430–470 cr and interest accretion are non-cash/financing-related
B27: Accruals ratio = (net profit − CFO) / average total assets | C27: % | E27: =(E10-E22)/AVERAGE(D18,E18) -> -0.05731169 | F27: =(F10-F22)/AVERAGE(E18,F18) -> -0.06411387 | G27: =(G10-G22)/AVERAGE(F18,G18) -> -0.064724446 | I27: Strongly negative = conservative earnings (cash > accounting profit)
B28: Free cash flow after capex / EBITDA | C28: x | D28: =(D22+D24)/D8 -> 0.97309939 | E28: =(E22+E24)/E8 -> 1.1620945 | F28: =(F22+F24)/F8 -> 1.0073657 | G28: =(G22+G24)/G8 -> 1.0675028
B29: Cash tax as % of P&L tax | C29: % | D29: =IFERROR(ABS(D23)/ABS(Fin_Proj!D36),0) -> 0.79167799 | E29: =IFERROR(ABS(E23)/ABS(Fin_Proj!E36),0) -> 2.8240882 | F29: =IFERROR(ABS(F23)/ABS(Fin_Proj!F36),0) -> 0.37220793 | G29: =IFERROR(ABS(G23)/ABS(Fin_Proj!G36),0) -> 0.091734179 | I29: Most REIT SPV tax is deferred; supports cash-tax ramp assumption in Fin_Proj row 14 (FY25: ~9%)
B31: D. Leverage and coverage
B32: Net debt / EBITDA | C32: x | D32: =D19/D8 -> 7.9418294 | E32: =E19/E8 -> 6.3687257 | F32: =F19/F8 -> 9.1965847 | G32: =G19/G8 -> 4.8516439 | H32: =H19/H8 -> 7.3764335 | I32: FY26 uses year-end debt on a full-year EBITDA that includes only ~4 months of Ecoworld – overstated
B33: EBIT / interest | C33: x | D33: =Fin_Proj!D32/Fin_Proj!D34 -> 1.9697021 | E33: =Fin_Proj!E32/Fin_Proj!E34 -> 1.2494855 | F33: =Fin_Proj!F32/Fin_Proj!F34 -> 0.9899217 | G33: =Fin_Proj!G32/Fin_Proj!G34 -> 1.2057324 | H33: =Fin_Proj!H32/Fin_Proj!H34 -> 1.7100651
B34: EBITDA / interest | C34: x | D34: =Fin_Proj!D29/Fin_Proj!D34 -> 2.971663 | E34: =Fin_Proj!E29/Fin_Proj!E34 -> 1.885854 | F34: =Fin_Proj!F29/Fin_Proj!F34 -> 1.4723008 | G34: =Fin_Proj!G29/Fin_Proj!G34 -> 1.6044527 | H34: =Fin_Proj!H29/Fin_Proj!H34 -> 2.1916117
B35: Debt / book equity | C35: x | D35: =D16/D14 -> 0.5815672 | E35: =E16/E14 -> 0.65421279 | F35: =F16/F14 -> 1.1908442 | G35: =G16/G14 -> 0.64565764
B37: E. Du Pont and returns on book capital
B38: Net margin | C38: % | D38: =D10/D6 -> 0.28088101 | E38: =E10/E6 -> 0.10961892 | F38: =F10/F6 -> 0.011644201 | G38: =G10/G6 -> 0.079076375
B39: Asset turnover (revenue / total assets) | C39: x | D39: =D6/D18 -> 0.060844946 | E39: =E6/E18 -> 0.083872685 | F39: =F6/F18 -> 0.071002979 | G39: =G6/G18 -> 0.091064085
B40: Equity multiplier (total assets / book equity) | C40: x | D40: =D18/D14 -> 1.6223937 | E40: =E18/E14 -> 1.7125111 | F40: =F18/F14 -> 2.476862 | G40: =G18/G14 -> 1.8672129
B41: ROE (Du Pont product) | C41: % | D41: =D38*D39*D40 -> 0.027727017 | E41: =E38*E39*E40 -> 0.015744885 | F41: =F38*F39*F40 -> 0.0020478026 | G41: =G38*G39*G40 -> 0.013445833
B42: ROIC = EBIT x (1 − t) / (equity + MI + debt − cash) | C42: % | D42: =Fin_Proj!D32*(1-Inputs!$C$42)/(D14+D15+D19) -> 0.022234999 | E42: =Fin_Proj!E32*(1-Inputs!$C$42)/(E14+E15+E19) -> 0.029889875 | F42: =Fin_Proj!F32*(1-Inputs!$C$42)/(F14+F15+F19) -> 0.026671406 | G42: =Fin_Proj!G32*(1-Inputs!$C$42)/(G14+G15+G19) -> 0.039862679 | I42: Low because the cost model carries assets far below fair value – hence EVA is also run on fair-value capital
B43: Book value per unit | C43: Rs | G43: 230.847 | I43: 'Balance Sheet'!F62
B44: Reported NAV per unit (31-Mar-26) | C44: Rs | H44: =Inputs!$C$13 -> 386.66
...

Sheet Rev_Build
B1: REVENUE BUILD – asset-wise leasing engine (replicates 'Revenue Estimation' with live formulas)
B2: Area in '000 sq ft · Rent in Rs/sq ft/month · Revenue in Rs million unless stated · Inputs trace to user model sheets named in column U
B5: 1. Asset parameter table (inputs from user model: Property wise / Quarterly Expected Occupancy / Revenue Estimation)
B7: Asset | C7: REIT own % | D7: Op. area FY27 | E7: Leased area (Q4FY26) | F7: In-place rent | G7: Rent escalator | H7: Area expiring FY27 | I7: Area expiring FY28 | J7: Area expiring FY29 | K7: New-leasing rent FY27 | L7: Renewal rent FY27 | M7: Exp. occupancy FY27 | N7: Exp. occupancy FY28 | O7: Exp. occupancy FY29 | P7: New-lease rent growth factor | Q7: Renewal rent growth factor | R7: Area added FY28 | S7: Area added FY29 | T7: CAM % of rental (OLR) | U7: Source
B8: Ecoworld, Bangalore | C8: 0.87 | D8: 7052 | E8: 6615 | F8: 105 | G8: 1.0294 | H8: 760 | I8: 309 | J8: 660 | K8: 106 | L8: 110 | M8: 0.94 | N8: 0.945 | O8: 0.9525 | P8: 1.06 | Q8: 1.06 | R8: 50 | S8: 50 | T8: 0.24697739 | U8: 'Revenue Estimation' rows 4/19/36; 'Property wise' CL:CM, DM/DP/DS; 'Quarterly Expected Occupancy' DL:DN
B9: Downtown Powai, Mumbai | C9: 0.5 | D9: 4461 | E9: 4232 | F9: 168 | G9: 1.0182 | H9: 327 | I9: 613 | J9: 415 | K9: 174 | L9: 182 | M9: 0.935 | N9: 0.9525 | O9: 0.9575 | P9: 1.04 | Q9: 1.06 | R9: 0 | S9: 0 | T9: 0.11356953 | U9: 'Revenue Estimation' rows 5/20/37; 'Property wise' CL:CM, DM/DP/DS; 'Quarterly Expected Occupancy' DL:DN
B10: G1, Gurugram | C10: 0.5 | D10: 3778 | E10: 3238 | F10: 85 | G10: 1.0162378 | H10: 131 | I10: 226 | J10: 0 | K10: 86 | L10: 91 | M10: 0.8825 | N10: 0.91 | O10: 0.925 | P10: 1.03 | Q10: 1.06 | R10: 25 | S10: 25 | T10: 0.40788801 | U10: 'Revenue Estimation' rows 6/21/38; 'Property wise' CL:CM, DM/DP/DS; 'Quarterly Expected Occupancy' DL:DN
B11: G2, Gurugram | C11: 1 | D11: 4060 | E11: 3367 | F11: 92 | G11: 1.02 | H11: 151 | I11: 0 | J11: 13 | K11: 88 | L11: 88 | M11: 0.8275 | N11: 0.82 | O11: 0.84 | P11: 1.03 | Q11: 1.06 | R11: 25 | S11: 25 | T11: 0.5550621 | U11: 'Revenue Estimation' rows 7/22/39; 'Property wise' CL:CM, DM/DP/DS; 'Quarterly Expected Occupancy' DL:DN
B12: N1, Noida | C12: 1 | D12: 2017 | E12: 1944 | F12: 66 | G12: 1.0264569 | H12: 98 | I12: 0 | J12: 102 | K12: 69 | L12: 69 | M12: 0.98 | N12: 0.98 | O12: 0.98 | P12: 1.03 | Q12: 1.06 | R12: 100 | S12: 150 | T12: 0.75332786 | U12: 'Revenue Estimation' rows 8/23/40; 'Property wise' CL:CM, DM/DP/DS; 'Quarterly Expected Occupancy' DL:DN
B13: N2, Noida | C13: 1 | D13: 3905 | E13: 3573 | F13: 66 | G13: 1.0154 | H13: 818 | I13: 44 | J13: 130 | K13: 66 | L13: 71 | M13: 0.9425 | N13: 0.9475 | O13: 0.955 | P13: 1.03 | Q13: 1.06 | R13: 100 | S13: 150 | T13: 0.54869542 | U13: 'Revenue Estimation' rows 9/24/41; 'Property wise' CL:CM, DM/DP/DS; 'Quarterly Expected Occupancy' DL:DN
B14: K1, Kolkata | C14: 1 | D14: 3167 | E14: 3130 | F14: 49 | G14: 1.0091213 | H14: 306 | I14: 438 | J14: 5 | K14: 54 | L14: 62 | M14: 0.98 | N14: 0.98 | O14: 0.9875 | P14: 1.04 | Q14: 1.06 | R14: 150 | S14: 250 | T14: 0.5854376 | U14: 'Revenue Estimation' rows 10/25/42; 'Property wise' CL:CM, DM/DP/DS; 'Quarterly Expected Occupancy' DL:DN
B15: Worldmark, Delhi (NCP) | C15: 0.5 | D15: 1455 | E15: 1384 | F15: 230 | G15: 1.03 | H15: 136 | I15: 151 | J15: 36 | K15: 237 | L15: 236 | M15: 0.96 | N15: 0.96 | O15: 0.96 | P15: 1.1 | Q15: 1.06 | R15: 0 | S15: 0 | T15: 0 | U15: 'Revenue Estimation' rows 11/26/43; 'Property wise' CL:CM, DM/DP/DS; 'Quarterly Expected Occupancy' DL:DN
B16: Worldmark, Gurugram (NCP) | C16: 0.5 | D16: 751 | E16: 695 | F16: 94 | G16: 1.03 | H16: 27 | I16: 20 | J16: 37 | K16: 93 | L16: 95 | M16: 0.92 | N16: 0.92 | O16: 0.92 | P16: 1.05 | Q16: 1.06 | R16: 0 | S16: 0 | T16: 0 | U16: 'Revenue Estimation' rows 12/27/44; 'Property wise' CL:CM, DM/DP/DS; 'Quarterly Expected Occupancy' DL:DN
B17: Airtel Center + Pavilion (NCP) | C17: 0.5 | F17: 1404 | G17: 1.05 | U17: User hard-code 'Revenue Estimation'!T14 = 1404*1.05 (annual rental Rs mn), grown 5% p.a. (T29, T46)
B18: Airtel/Pavilion: F17 = FY26 run-rate rental (Rs mn), G17 = annual growth factor. NCP rows are equity-accounted (not in consolidated revenue).
B21: FY27E – asset engine (continuing + expiring + vacancy absorption)
B22: Asset | C22: Own % | D22: Operating area | E22: Leased area (open) | F22: Vacant | G22: Area expiring | H22: Continuing area | I22: In-place rent | J22: Escalator | K22: Continuing rent | L22: New-leasing rent | M22: Renewal rent | N22: Continuing rev | O22: Expiry rev (50%) | P22: Vacancy rev (50%) | Q22: Exp. occupancy | R22: Exp. leased area | S22: Absorbed area | T22: Absorption ratio | U22: Re-leasing rev | V22: Total rental | W22: CAM % | X22: CAM revenue | Y22: Total revenue (Rs mn) | Z22: Revenue (Rs cr)
B23: Ecoworld, Bangalore | C23: =C8 -> 0.87 | D23: =D8 -> 7052 | E23: =E8 -> 6615 | F23: =D23-E23 -> 437 | G23: =H8 -> 760 | H23: =E23-G23 -> 5855 | I23: =F8 -> 105 | J23: =G8 -> 1.0294 | K23: =I23*J23 -> 108.087 | L23: =K8 -> 106 | M23: =L8 -> 110 | N23: =H23*K23*12/1000 -> 7594.1926 | O23: =G23*M23*12/1000*0.5 -> 501.6 | P23: =F23*L23*12/1000*0.5 -> 277.932 | Q23: =M8 -> 0.94 | R23: =Q23*D23 -> 6628.88 | S23: =MAX(0,R23-H23) -> 773.88 | T23: =IFERROR(S23/(G23+F23),0) -> 0.64651629 | U23: =(O23+P23)*T23 -> 503.98014 | V23: =N23+U23 -> 8098.1728 | W23: =T8 -> 0.24697739 | X23: =V23*W23 -> 2000.0656 | Y23: =V23+X23 -> 10098.238 | Z23: =Y23/10 -> 1009.8238
B24: Downtown Powai, Mumbai | C24: =C9 -> 0.5 | D24: =D9 -> 4461 | E24: =E9 -> 4232 | F24: =D24-E24 -> 229 | G24: =H9 -> 327 | H24: =E24-G24 -> 3905 | I24: =F9 -> 168 | J24: =G9 -> 1.0182 | K24: =I24*J24 -> 171.0576 | L24: =K9 -> 174 | M24: =L9 -> 182 | N24: =H24*K24*12/1000 -> 8015.7591 | O24: =G24*M24*12/1000*0.5 -> 357.084 | P24: =F24*L24*12/1000*0.5 -> 239.076 | Q24: =M9 -> 0.935 | R24: =Q24*D24 -> 4171.035 | S24: =MAX(0,R24-H24) -> 266.035 | T24: =IFERROR(S24/(G24+F24),0) -> 0.47848022 | U24: =(O24+P24)*T24 -> 285.25077 | V24: =N24+U24 -> 8301.0099 | W24: =T9 -> 0.11356953 | X24: =V24*W24 -> 942.74176 | Y24: =V24+X24 -> 9243.7517 | Z24: =Y24/10 -> 924.37517
B25: G1, Gurugram | C25: =C10 -> 0.5 | D25: =D10 -> 3778 | E25: =E10 -> 3238 | F25: =D25-E25 -> 540 | G25: =H10 -> 131 | H25: =E25-G25 -> 3107 | I25: =F10 -> 85 | J25: =G10 -> 1.0162378 | K25: =I25*J25 -> 86.380213 | L25: =K10 -> 86 | M25: =L10 -> 91 | N25: =H25*K25*12/1000 -> 3220.5999 | O25: =G25*M25*12/1000*0.5 -> 71.526 | P25: =F25*L25*12/1000*0.5 -> 278.64 | Q25: =M10 -> 0.8825 | R25: =Q25*D25 -> 3334.085 | S25: =MAX(0,R25-H25) -> 227.085 | T25: =IFERROR(S25/(G25+F25),0) -> 0.33842772 | U25: =(O25+P25)*T25 -> 118.50588 | V25: =N25+U25 -> 3339.1057 | W25: =T10 -> 0.40788801 | X25: =V25*W25 -> 1361.9812 | Y25: =V25+X25 -> 4701.0869 | Z25: =Y25/10 -> 470.10869
B26: G2, Gurugram | C26: =C11 -> 1 | D26: =D11 -> 4060 | E26: =E11 -> 3367 | F26: =D26-E26 -> 693 | G26: =H11 -> 151 | H26: =E26-G26 -> 3216 | I26: =F11 -> 92 | J26: =G11 -> 1.02 | K26: =I26*J26 -> 93.84 | L26: =K11 -> 88 | M26: =L11 -> 88 | N26: =H26*K26*12/1000 -> 3621.4733 | O26: =G26*M26*12/1000*0.5 -> 79.728 | P26: =F26*L26*12/1000*0.5 -> 365.904 | Q26: =M11 -> 0.8275 | R26: =Q26*D26 -> 3359.65 | S26: =MAX(0,R26-H26) -> 143.65 | T26: =IFERROR(S26/(G26+F26),0) -> 0.17020142 | U26: =(O26+P26)*T26 -> 75.8472 | V26: =N26+U26 -> 3697.3205 | W26: =T11 -> 0.5550621 | X26: =V26*W26 -> 2052.2425 | Y26: =V26+X26 -> 5749.5629 | Z26: =Y26/10 -> 574.95629
B27: N1, Noida | C27: =C12 -> 1 | D27: =D12 -> 2017 | E27: =E12 -> 1944 | F27: =D27-E27 -> 73 | G27: =H12 -> 98 | H27: =E27-G27 -> 1846 | I27: =F12 -> 66 | J27: =G12 -> 1.0264569 | K27: =I27*J27 -> 67.746157 | L27: =K12 -> 69 | M27: =L12 -> 69 | N27: =H27*K27*12/1000 -> 1500.7129 | O27: =G27*M27*12/1000*0.5 -> 40.572 | P27: =F27*L27*12/1000*0.5 -> 30.222 | Q27: =M12 -> 0.98 | R27: =Q27*D27 -> 1976.66 | S27: =MAX(0,R27-H27) -> 130.66 | T27: =IFERROR(S27/(G27+F27),0) -> 0.76409357 | U27: =(O27+P27)*T27 -> 54.09324 | V27: =N27+U27 -> 1554.8061 | W27: =T12 -> 0.75332786 | X27: =V27*W27 -> 1171.2788 | Y27: =V27+X27 -> 2726.0849 | Z27: =Y27/10 -> 272.60849
B28: N2, Noida | C28: =C13 -> 1 | D28: =D13 -> 3905 | E28: =E13 -> 3573 | F28: =D28-E28 -> 332 | G28: =H13 -> 818 | H28: =E28-G28 -> 2755 | I28: =F13 -> 66 | J28: =G13 -> 1.0154 | K28: =I28*J28 -> 67.0164 | L28: =K13 -> 66 | M28: =L13 -> 71 | N28: =H28*K28*12/1000 -> 2215.5622 | O28: =G28*M28*12/1000*0.5 -> 348.468 | P28: =F28*L28*12/1000*0.5 -> 131.472 | Q28: =M13 -> 0.9425 | R28: =Q28*D28 -> 3680.4625 | S28: =MAX(0,R28-H28) -> 925.4625 | T28: =IFERROR(S28/(G28+F28),0) -> 0.80475 | U28: =(O28+P28)*T28 -> 386.23172 | V28: =N28+U28 -> 2601.7939 | W28: =T13 -> 0.54869542 | X28: =V28*W28 -> 1427.5924 | Y28: =V28+X28 -> 4029.3863 | Z28: =Y28/10 -> 402.93863
B29: K1, Kolkata | C29: =C14 -> 1 | D29: =D14 -> 3167 | E29: =E14 -> 3130 | F29: =D29-E29 -> 37 | G29: =H14 -> 306 | H29: =E29-G29 -> 2824 | I29: =F14 -> 49 | J29: =G14 -> 1.0091213 | K29: =I29*J29 -> 49.446943 | L29: =K14 -> 54 | M29: =L14 -> 62 | N29: =H29*K29*12/1000 -> 1675.658 | O29: =G29*M29*12/1000*0.5 -> 113.832 | P29: =F29*L29*12/1000*0.5 -> 11.988 | Q29: =M14 -> 0.98 | R29: =Q29*D29 -> 3103.66 | S29: =MAX(0,R29-H29) -> 279.66 | T29: =IFERROR(S29/(G29+F29),0) -> 0.81533528 | U29: =(O29+P29)*T29 -> 102.58548 | V29: =N29+U29 -> 1778.2435 | W29: =T14 -> 0.5854376 | X29: =V29*W29 -> 1041.0506 | Y29: =V29+X29 -> 2819.2941 | Z29: =Y29/10 -> 281.92941
B30: Worldmark, Delhi (NCP) | C30: =C15 -> 0.5 | D30: =D15 -> 1455 | E30: =E15 -> 1384 | F30: =D30-E30 -> 71 | G30: =H15 -> 136 | H30: =E30-G30 -> 1248 | I30: =F15 -> 230 | J30: =G15 -> 1.03 | K30: =I30*J30 -> 236.9 | L30: =K15 -> 237 | M30: =L15 -> 236 | N30: =H30*K30*12/1000 -> 3547.8144 | O30: =G30*M30*12/1000*0.5 -> 192.576 | P30: =F30*L30*12/1000*0.5 -> 100.962 | Q30: =M15 -> 0.96 | R30: =Q30*D30 -> 1396.8 | S30: =MAX(0,R30-H30) -> 148.8 | T30: =IFERROR(S30/(G30+F30),0) -> 0.71884058 | U30: =(O30+P30)*T30 -> 211.00703 | V30: =N30+U30 -> 3758.8214 | W30: =T15 -> 0 | X30: =V30*W30 -> 0 | Y30: =V30+X30 -> 3758.8214 | Z30: =Y30/10 -> 375.88214
B31: Worldmark, Gurugram (NCP) | C31: =C16 -> 0.5 | D31: =D16 -> 751 | E31: =E16 -> 695 | F31: =D31-E31 -> 56 | G31: =H16 -> 27 | H31: =E31-G31 -> 668 | I31: =F16 -> 94 | J31: =G16 -> 1.03 | K31: =I31*J31 -> 96.82 | L31: =K16 -> 93 | M31: =L16 -> 95 | N31: =H31*K31*12/1000 -> 776.10912 | O31: =G31*M31*12/1000*0.5 -> 15.39 | P31: =F31*L31*12/1000*0.5 -> 31.248 | Q31: =M16 -> 0.92 | R31: =Q31*D31 -> 690.92 | S31: =MAX(0,R31-H31) -> 22.92 | T31: =IFERROR(S31/(G31+F31),0) -> 0.27614458 | U31: =(O31+P31)*T31 -> 12.878831 | V31: =N31+U31 -> 788.98795 | W31: =T16 -> 0 | X31: =V31*W31 -> 0 | Y31: =V31+X31 -> 788.98795 | Z31: =Y31/10 -> 78.898795
B32: Airtel Center + Pavilion (NCP) | C32: =C17 -> 0.5 | V32: =$F$17*$G$17^1 -> 1474.2 | Y32: =V32 -> 1474.2 | Z32: =Y32/10 -> 147.42
B33: Consolidated assets (7) | D33: =SUM(D23:D29) -> 28440 | E33: =SUM(E23:E29) -> 26099 | F33: =SUM(F23:F29) -> 2341 | G33: =SUM(G23:G29) -> 2591 | H33: =SUM(H23:H29) -> 23508 | N33: =SUM(N23:N29) -> 27843.958 | O33: =SUM(O23:O29) -> 1512.81 | P33: =SUM(P23:P29) -> 1335.234 | Q33: =R33/D33 -> 0.92315164 | R33: =SUM(R23:R29) -> 26254.433 | S33: =SUM(S23:S29) -> 2746.4325 | U33: =SUM(U23:U29) -> 1526.4944 | V33: =SUM(V23:V29) -> 29370.452 | X33: =SUM(X23:X29) -> 9996.9528 | Y33: =SUM(Y23:Y29) -> 39367.405 | Z33: =SUM(Z23:Z29) -> 3936.7405
B34: North Commercial Portfolio rental (3 lines, 100%) | V34: =SUM(V30:V32) -> 6022.0094 | Z34: =V34/10 -> 602.20094
B35: Consolidated revenue (Rs cr) = (rental + CAM) / 10 | Z35: =Y33/10 -> 3936.7405
B38: FY28E – asset engine (continuing + expiring + vacancy absorption)
B39: Asset | C39: Own % | D39: Operating area | E39: Leased area (open) | F39: Vacant | G39: Area expiring | H39: Continuing area | I39: In-place rent | J39: Escalator | K39: Continuing rent | L39: New-leasing rent | M39: Renewal rent | N39: Continuing rev | O39: Expiry rev (50%) | P39: Vacancy rev (50%) | Q39: Exp. occupancy | R39: Exp. leased area | S39: Absorbed area | T39: Absorption ratio | U39: Re-leasing rev | V39: Total rental | W39: CAM % | X39: CAM revenue | Y39: Total revenue (Rs mn) | Z39: Revenue (Rs cr)
B40: Ecoworld, Bangalore | C40: =C8 -> 0.87 | D40: =D23+R8 -> 7102 | E40: =R23 -> 6628.88 | F40: =D40-E40 -> 473.12 | G40: =I8 -> 309 | H40: =E40-G40 -> 6319.88 | I40: =K23 -> 108.087 | J40: =G8 -> 1.0294 | K40: =I40*J40 -> 111.26476 | L40: =L23*P8 -> 112.36 | M40: =M23*Q8 -> 116.6 | N40: =H40*K40*12/1000 -> 8438.159 | O40: =G40*M40*12/1000*0.5 -> 216.1764 | P40: =F40*L40*12/1000*0.5 -> 318.95858 | Q40: =N8 -> 0.945 | R40: =Q40*D40 -> 6711.39 | S40: =MAX(0,R40-H40) -> 391.51 | T40: =IFERROR(S40/(G40+F40),0) -> 0.50057536 | U40: =(O40+P40)*T40 -> 267.87538 | V40: =N40+U40 -> 8706.0344 | W40: =T8 -> 0.24697739 | X40: =V40*W40 -> 2150.1936 | Y40: =V40+X40 -> 10856.228 | Z40: =Y40/10 -> 1085.6228
B41: Downtown Powai, Mumbai | C41: =C9 -> 0.5 | D41: =D24+R9 -> 4461 | E41: =R24 -> 4171.035 | F41: =D41-E41 -> 289.965 | G41: =I9 -> 613 | H41: =E41-G41 -> 3558.035 | I41: =K24 -> 171.0576 | J41: =G9 -> 1.0182 | K41: =I41*J41 -> 174.17085 | L41: =L24*P9 -> 180.96 | M41: =M24*Q9 -> 192.92 | N41: =H41*K41*12/1000 -> 7436.4717 | O41: =G41*M41*12/1000*0.5 -> 709.55976 | P41: =F41*L41*12/1000*0.5 -> 314.8324 | Q41: =N9 -> 0.9525 | R41: =Q41*D41 -> 4249.1025 | S41: =MAX(0,R41-H41) -> 691.0675 | T41: =IFERROR(S41/(G41+F41),0) -> 0.76533144 | U41: =(O41+P41)*T41 -> 783.99952 | V41: =N41+U41 -> 8220.4712 | W41: =T9 -> 0.11356953 | X41: =V41*W41 -> 933.59502 | Y41: =V41+X41 -> 9154.0662 | Z41: =Y41/10 -> 915.40662
B42: G1, Gurugram | C42: =C10 -> 0.5 | D42: =D25+R10 -> 3803 | E42: =R25 -> 3334.085 | F42: =D42-E42 -> 468.915 | G42: =I10 -> 226 | H42: =E42-G42 -> 3108.085 | I42: =K25 -> 86.380213 | J42: =G10 -> 1.0162378 | K42: =I42*J42 -> 87.782837 | L42: =L25*P10 -> 88.58 | M42: =M25*Q10 -> 96.46 | N42: =H42*K42*12/1000 -> 3274.0382 | O42: =G42*M42*12/1000*0.5 -> 130.79976 | P42: =F42*L42*12/1000*0.5 -> 249.21894 | Q42: =N10 -> 0.91 | R42: =Q42*D42 -> 3460.73 | S42: =MAX(0,R42-H42) -> 352.645 | T42: =IFERROR(S42/(G42+F42),0) -> 0.50746494 | U42: =(O42+P42)*T42 -> 192.84617 | V42: =N42+U42 -> 3466.8844 | W42: =T10 -> 0.40788801 | X42: =V42*W42 -> 1414.1006 | Y42: =V42+X42 -> 4880.985 | Z42: =Y42/10 -> 488.0985
B43: G2, Gurugram | C43: =C11 -> 1 | D43: =D26+R11 -> 4085 | E43: =R26 -> 3359.65 | F43: =D43-E43 -> 725.35 | G43: =I11 -> 0 | H43: =E43-G43 -> 3359.65 | I43: =K26 -> 93.84 | J43: =G11 -> 1.02 | K43: =I43*J43 -> 95.7168 | L43: =L26*P11 -> 90.64 | M43: =M26*Q11 -> 93.28 | N43: =H43*K43*12/1000 -> 3858.8994 | O43: =G43*M43*12/1000*0.5 -> 0 | P43: =F43*L43*12/1000*0.5 -> 394.47434 | Q43: =N11 -> 0.82 | R43: =Q43*D43 -> 3349.7 | S43: =MAX(0,R43-H43) -> 0 | T43: =IFERROR(S43/(G43+F43),0) -> 0 | U43: =(O43+P43)*T43 -> 0 | V43: =N43+U43 -> 3858.8994 | W43: =T11 -> 0.5550621 | X43: =V43*W43 -> 2141.9288 | Y43: =V43+X43 -> 6000.8281 | Z43: =Y43/10 -> 600.08281
B44: N1, Noida | C44: =C12 -> 1 | D44: =D27+R12 -> 2117 | E44: =R27 -> 1976.66 | F44: =D44-E44 -> 140.34 | G44: =I12 -> 0 | H44: =E44-G44 -> 1976.66 | I44: =K27 -> 67.746157 | J44: =G12 -> 1.0264569 | K44: =I44*J44 -> 69.538511 | L44: =L27*P12 -> 71.07 | M44: =M27*Q12 -> 73.14 | N44: =H44*K44*12/1000 -> 1649.4479 | O44: =G44*M44*12/1000*0.5 -> 0 | P44: =F44*L44*12/1000*0.5 -> 59.843783 | Q44: =N12 -> 0.98 | R44: =Q44*D44 -> 2074.66 | S44: =MAX(0,R44-H44) -> 98 | T44: =IFERROR(S44/(G44+F44),0) -> 0.69830412 | U44: =(O44+P44)*T44 -> 41.78916 | V44: =N44+U44 -> 1691.2371 | W44: =T12 -> 0.75332786 | X44: =V44*W44 -> 1274.056 | Y44: =V44+X44 -> 2965.2931 | Z44: =Y44/10 -> 296.52931
B45: N2, Noida | C45: =C13 -> 1 | D45: =D28+R13 -> 4005 | E45: =R28 -> 3680.4625 | F45: =D45-E45 -> 324.5375 | G45: =I13 -> 44 | H45: =E45-G45 -> 3636.4625 | I45: =K28 -> 67.0164 | J45: =G13 -> 1.0154 | K45: =I45*J45 -> 68.048453 | L45: =L28*P13 -> 67.98 | M45: =M28*Q13 -> 75.26 | N45: =H45*K45*12/1000 -> 2969.4678 | O45: =G45*M45*12/1000*0.5 -> 19.86864 | P45: =F45*L45*12/1000*0.5 -> 132.37236 | Q45: =N13 -> 0.9475 | R45: =Q45*D45 -> 3794.7375 | S45: =MAX(0,R45-H45) -> 158.275 | T45: =IFERROR(S45/(G45+F45),0) -> 0.42946783 | U45: =(O45+P45)*T45 -> 65.38261 | V45: =N45+U45 -> 3034.8504 | W45: =T13 -> 0.54869542 | X45: =V45*W45 -> 1665.2085 | Y45: =V45+X45 -> 4700.0588 | Z45: =Y45/10 -> 470.00588
B46: K1, Kolkata | C46: =C14 -> 1 | D46: =D29+R14 -> 3317 | E46: =R29 -> 3103.66 | F46: =D46-E46 -> 213.34 | G46: =I14 -> 438 | H46: =E46-G46 -> 2665.66 | I46: =K29 -> 49.446943 | J46: =G14 -> 1.0091213 | K46: =I46*J46 -> 49.897964 | L46: =L29*P14 -> 56.16 | M46: =M29*Q14 -> 65.72 | N46: =H46*K46*12/1000 -> 1596.1321 | O46: =G46*M46*12/1000*0.5 -> 172.71216 | P46: =F46*L46*12/1000*0.5 -> 71.887046 | Q46: =N14 -> 0.98 | R46: =Q46*D46 -> 3250.66 | S46: =MAX(0,R46-H46) -> 585 | T46: =IFERROR(S46/(G46+F46),0) -> 0.89814843 | U46: =(O46+P46)*T46 -> 219.68639 | V46: =N46+U46 -> 1815.8185 | W46: =T14 -> 0.5854376 | X46: =V46*W46 -> 1063.0484 | Y46: =V46+X46 -> 2878.8669 | Z46: =Y46/10 -> 287.88669
B47: Worldmark, Delhi (NCP) | C47: =C15 -> 0.5 | D47: =D30+R15 -> 1455 | E47: =R30 -> 1396.8 | F47: =D47-E47 -> 58.2 | G47: =I15 -> 151 | H47: =E47-G47 -> 1245.8 | I47: =K30 -> 236.9 | J47: =G15 -> 1.03 | K47: =I47*J47 -> 244.007 | L47: =L30*P15 -> 260.7 | M47: =M30*Q15 -> 250.16 | N47: =H47*K47*12/1000 -> 3647.807 | O47: =G47*M47*12/1000*0.5 -> 226.64496 | P47: =F47*L47*12/1000*0.5 -> 91.03644 | Q47: =N15 -> 0.96 | R47: =Q47*D47 -> 1396.8 | S47: =MAX(0,R47-H47) -> 151 | T47: =IFERROR(S47/(G47+F47),0) -> 0.72179732 | U47: =(O47+P47)*T47 -> 229.30158 | V47: =N47+U47 -> 3877.1086 | W47: =T15 -> 0 | X47: =V47*W47 -> 0 | Y47: =V47+X47 -> 3877.1086 | Z47: =Y47/10 -> 387.71086
...

Sheet Fin_Proj
B1: FINANCIAL PROJECTIONS – income statement, debt schedule, capex and NDCF/DPU (consolidated, Rs crore)
B2: FY22A–FY26A from user model 'Quarterly-data'!AN:AR · FY27E–FY29E revenue from Rev_Build · FY30E–FY36E driver-based fade
B4: Rs crore | C4: Unit | D4: FY22A | E4: FY23A | F4: FY24A | G4: FY25A | H4: FY26A | I4: FY27E | J4: FY28E | K4: FY29E | L4: FY30E | M4: FY31E | N4: FY32E | O4: FY33E | P4: FY34E | Q4: FY35E | R4: FY36E
B5: Projection year index | I5: 1 | J5: 2 | K5: 3 | L5: 4 | M5: 5 | N5: 6 | O5: 7 | P5: 8 | Q5: 9 | R5: 10
B6: Forecast drivers (green = assumption)
B7: Revenue growth (FY30E+) | C7: % | L7: 0.05 | M7: 0.05 | N7: 0.05 | O7: 0.05 | P7: 0.05 | Q7: 0.05 | R7: 0.05 | T7: ASSUMPTION – ~in-place escalation 4.8%/yr + MTM; fades toward terminal growth. FY27–29 come from Rev_Build
B8: Cost of services (% of revenue) | C8: % | I8: 0.003792814 | J8: 0.0036627584 | K8: 0.0037059687 | L8: =K8 -> 0.0037059687 | M8: =K8 -> 0.0037059687 | N8: =K8 -> 0.0037059687 | O8: =K8 -> 0.0037059687 | P8: =K8 -> 0.0037059687 | Q8: =K8 -> 0.0037059687 | R8: =K8 -> 0.0037059687 | T8: User model Quarterly-data rows 11/3
B9: Operating expenses (% of revenue) | C9: % | I9: 0.28005 | J9: 0.259975 | K9: 0.25 | L9: =K9 -> 0.25 | M9: =K9 -> 0.25 | N9: =K9 -> 0.25 | O9: =K9 -> 0.25 | P9: =K9 -> 0.25 | Q9: =K9 -> 0.25 | R9: =K9 -> 0.25 | T9: User model: 28% / 26% / 25%; held at 25% thereafter
B10: Employee cost (% of revenue) | C10: % | I10: 0.011 | J10: 0.011 | K10: 0.011 | L10: =K10 -> 0.011 | M10: =K10 -> 0.011 | N10: =K10 -> 0.011 | O10: =K10 -> 0.011 | P10: =K10 -> 0.011 | Q10: =K10 -> 0.011 | R10: =K10 -> 0.011 | T10: User model: 1.1%
B11: Other income (% of revenue) | C11: % | I11: 0.036204967 | J11: 0.03531722 | K11: 0.035279573 | L11: 0.035 | M11: 0.035 | N11: 0.035 | O11: 0.035 | P11: 0.035 | Q11: 0.035 | R11: 0.035 | T11: User model average-ratio method; 3.5% thereafter
B12: Depreciation growth (FY30E+) | C12: % | L12: 0.01 | M12: 0.01 | N12: 0.01 | O12: 0.01 | P12: 0.01 | Q12: 0.01 | R12: 0.01 | T12: ASSUMPTION – operating area flat after FY29 in explicit build
B13: Effective tax rate on PBT (P&L) | C13: % | I13: 0.24 | J13: 0.25 | K13: 0.26 | L13: =Inputs!$C$42 -> 0.2517 | M13: =Inputs!$C$42 -> 0.2517 | N13: =Inputs!$C$42 -> 0.2517 | O13: =Inputs!$C$42 -> 0.2517 | P13: =Inputs!$C$42 -> 0.2517 | Q13: =Inputs!$C$42 -> 0.2517 | R13: =Inputs!$C$42 -> 0.2517 | T13: User model: 24%/25%/26%; statutory 25.17% from FY30E
B14: Cash (current) tax as % of P&L tax | C14: % | I14: 0.3 | J14: 0.4 | K14: 0.5 | L14: 0.6 | M14: 0.7 | N14: 0.8 | O14: 0.9 | P14: 1 | Q14: 1 | R14: 1 | T14: ASSUMPTION – FY25 tax paid Rs 8 cr vs P&L tax Rs 89.5 cr (~9%); shield assumed to erode to 100% by FY34E
B15: Refurbishment / repositioning capex | C15: Rs cr | I15: 150 | J15: 150 | K15: 150 | L15: 100 | M15: 100 | N15: 100 | O15: 100 | P15: 100 | Q15: 100 | R15: 100 | T15: ASSUMPTION – SEZ→NPA conversion, Ecoworld repositioning, tenant improvements
B16: Interest rate on average debt | C16: % | I16: 0.075 | J16: 0.075 | K16: 0.075 | L16: 0.075 | M16: 0.075 | N16: 0.075 | O16: 0.075 | P16: 0.075 | Q16: 0.075 | R16: 0.075 | T16: Q1 FY27 avg 7.3% (90% floating) + 25bp repo hike pass-through
B17: Minority interest in profit (P&L) | C17: Rs cr | I17: -55.521 | J17: -55.521 | K17: -55.521 | L17: -55.521 | M17: -55.521 | N17: -55.521 | O17: -55.521 | P17: -55.521 | Q17: -55.521 | R17: -55.521 | T17: User model Quarterly-data row 39 (held flat)
B18: Share of associates (NCP) | C18: Rs cr | I18: -40.284 | J18: -40.284 | K18: -40.284 | L18: -40.284 | M18: -40.284 | N18: -40.284 | O18: -40.284 | P18: -40.284 | Q18: -40.284 | R18: -40.284 | T18: User model Quarterly-data row 40 (held flat)
B19: Memo: user's coverage-ratio interest | C19: Rs cr | I19: 1027.2688 | J19: 1174.3513 | K19: 1319.6854 | T19: User model Quarterly-data row 32 (EBITDA/ICR − Rs 60 cr per quarter)
B22: Income statement
B24: Revenue from operations | D24: 876.791 | E24: 1196.999 | F24: 1780.481 | G24: 2385.592 | H24: 2962.259 | I24: =Rev_Build!$Z$35 -> 3936.7405 | J24: =Rev_Build!$Z$52 -> 4143.6326 | K24: =Rev_Build!$Z$69 -> 4352.1901 | L24: =K24*(1+L7) -> 4569.7996 | M24: =L24*(1+M7) -> 4798.2896 | N24: =M24*(1+N7) -> 5038.2041 | O24: =N24*(1+O7) -> 5290.1143 | P24: =O24*(1+P7) -> 5554.62 | Q24: =P24*(1+Q7) -> 5832.351 | R24: =Q24*(1+R7) -> 6123.9685
B25: growth % | E25: =E24/D24-1 -> 0.36520448 | F25: =F24/E24-1 -> 0.48745404 | G25: =G24/F24-1 -> 0.33985816 | H25: =H24/G24-1 -> 0.2417291 | I25: =I24/H24-1 -> 0.32896567 | J25: =J24/I24-1 -> 0.052554165 | K25: =K24/J24-1 -> 0.050332039 | L25: =L24/K24-1 -> 0.05 | ... R25: =R24/Q24-1 -> 0.05
B26: Cost of services | D26: 2.4130606 | E26: 5.5022564 | F26: 7.3817212 | G26: 8.3820322 | H26: 10.886709 | I26: =I24*I8 -> 14.931325 | J26: =J24*J8 -> 15.177125 | K26: =K24*K8 -> 16.12908 | L26: =L24*L8 -> 16.935534 | M26: =M24*M8 -> 17.782311 | N26: =N24*N8 -> 18.671427 | O26: =O24*O8 -> 19.604998 | P26: =P24*P8 -> 20.585248 | ... R26: =R24*R8 -> 22.695236
B27: Operating expenses | D27: 236.382 | E27: 341.215 | F27: 474.417 | G27: 622.578 | H27: 783.776 | I27: =I24*I9 -> 1102.4842 | J27: =J24*J9 -> 1077.2409 | K27: =K24*K9 -> 1088.0475 | L27: =L24*L9 -> 1142.4499 | M27: =M24*M9 -> 1199.5724 | N27: =N24*N9 -> 1259.551 | O27: =O24*O9 -> 1322.5286 | P27: =P24*P9 -> 1388.655 | ... R27: =R24*R9 -> 1530.9921
B28: Employee cost | D28: 19.685 | E28: 34.731 | F28: 43.989 | G28: 24.748 | H28: 31.257 | I28: =I24*I10 -> 43.304146 | J28: =J24*J10 -> 45.579959 | K28: =K24*K10 -> 47.874091 | L28: =L24*L10 -> 50.267796 | M28: =M24*M10 -> 52.781185 | N28: =N24*N10 -> 55.420245 | O28: =O24*O10 -> 58.191257 | P28: =P24*P10 -> 61.10082 | ... R28: =R24*R10 -> 67.363654
B29: EBITDA | D29: 618.31094 | E29: 815.55074 | F29: 1254.6933 | G29: 1729.884 | H29: 2136.3393 | I29: =I24-I26-I27-I28 -> 2776.0209 | J29: =J24-J26-J27-J28 -> 3005.6346 | K29: =K24-K26-K27-K28 -> 3200.1394 | L29: =L24-L26-L27-L28 -> 3360.1464 | M29: =M24-M26-M27-M28 -> 3528.1537 | N29: =N24-N26-N27-N28 -> 3704.5614 | O29: =O24-O26-O27-O28 -> 3889.7894 | P29: =P24-P26-P27-P28 -> 4084.2789 | ... R29: =R24-R26-R27-R28 -> 4502.9175
B30: EBITDA margin | D30: =D29/D24 -> 0.70519763 | E30: =E29/E24 -> 0.68132951 | F30: =F29/F24 -> 0.70469344 | G30: =G29/G24 -> 0.72513823 | H30: =H29/H24 -> 0.72118586 | I30: =I29/I24 -> 0.70515719 | J30: =J29/J24 -> 0.72536224 | K30: =K29/K24 -> 0.73529403 | ... R30: =R29/R24 -> 0.73529403
B31: Depreciation & amortisation | D31: 208.477 | E31: 275.202 | F31: 411.083 | G31: 429.891 | H31: 469.402 | I31: =Rev_Build!$D$33*Inputs!$C$48*4 -> 580 | J31: =Rev_Build!$D$50*Inputs!$C$48*4 -> 589.17722 | K31: =Rev_Build!$D$67*Inputs!$C$48*4 -> 602.43319 | L31: =K31*(1+L12) -> 608.45752 | M31: =L31*(1+M12) -> 614.5421 | N31: =M31*(1+N12) -> 620.68752 | O31: =N31*(1+O12) -> 626.8944 | P31: =O31*(1+P12) -> 633.16334 | Q31: =P31*(1+Q12) -> 639.49497 | R31: =Q31*(1+R12) -> 645.88992
B32: EBIT | D32: =D29-D31 -> 409.83394 | E32: =E29-E31 -> 540.34874 | F32: =F29-F31 -> 843.61028 | G32: =G29-G31 -> 1299.993 | H32: =H29-H31 -> 1666.9373 | I32: =I29-I31 -> 2196.0209 | J32: =J29-J31 -> 2416.4574 | K32: =K29-K31 -> 2597.7062 | ... R32: =R29-R31 -> 3857.0276
B33: Other income | D33: 22.423 | E33: 32.48 | F33: 70.673 | G33: 84.42 | H33: 100.187 | I33: =I24*I11 -> 142.52956 | J33: =J24*J11 -> 146.34159 | K33: =K24*K11 -> 153.54341 | L33: =L24*L11 -> 159.94299 | M33: =M24*M11 -> 167.94014 | N33: =N24*N11 -> 176.33714 | O33: =O24*O11 -> 185.154 | P33: =P24*P11 -> 194.4117 | ... R33: =R24*R11 -> 214.3389
B34: Interest expense | D34: 208.069 | E34: 432.457 | F34: 852.199 | G34: 1078.177 | H34: 974.78 | I34: =IF(Inputs!$C$51=1,I55,I19) -> 1116.2181 | J34: =IF(Inputs!$C$51=1,J55,J19) -> 1146.3587 | K34: =IF(Inputs!$C$51=1,K55,K19) -> 1178.9368 | L34: =L55 -> 1196.2337 | M34: =M55 -> 1203.7337 | N34: =N55 -> 1211.2337 | O34: =O55 -> 1218.7337 | P34: =P55 -> 1226.2337 | Q34: =Q55 -> 1233.7337 | R34: =R55 -> 1241.2337 | T34: Default = debt-schedule interest (rows 51–55). User's method implies debt rising ~Rs 4,000 cr by FY29 with no acquisition revenue in the build.
B35: Profit before tax | D35: =D32+D33-D34 -> 224.18794 | E35: =E32+E33-E34 -> 140.37174 | F35: =F32+F33-F34 -> 62.084279 | G35: =G32+G33-G34 -> 306.23597 | H35: =H32+H33-H34 -> 792.34429 | I35: =I32+I33-I34 -> 1222.3323 | J35: =J32+J33-J34 -> 1416.4403 | K35: =K32+K33-K34 -> 1572.3128 | ... R35: =R32+R33-R34 -> 2830.1328
B36: Tax | D36: -22.086 | E36: 9.158 | F36: 68.811 | G36: 88.255 | H36: 221.668 | I36: =I35*I13 -> 293.35976 | J36: =J35*J13 -> 354.11008 | K36: =K35*K13 -> 408.80132 | L36: =L35*L13 -> 431.76571 | M36: =M35*M13 -> 472.6468 | N36: =N35*N13 -> 515.72758 | O36: =O35*O13 -> 561.11867 | P36: =P35*P13 -> 608.93619 | ... R36: =R35*R13 -> 712.34442 | T36: FY26A tax Rs 221.7 cr includes Q4 charge of Rs 169.5 cr (75% of Q4 PBT) – treated as non-recurring in Hist_Quality.
B37: Profit after tax | D37: =D35-D36 -> 246.27394 | E37: =E35-E36 -> 131.21374 | F37: =F35-F36 -> -6.7267212 | G37: =G35-G36 -> 217.98097 | H37: =H35-H36 -> 570.67629 | I37: =I35-I36 -> 928.97258 | J37: =J35-J36 -> 1062.3302 | K37: =K35-K36 -> 1163.5115 | ... R37: =R35-R36 -> 2117.7884
B38: Minority interest | D38: 0 | E38: 0 | F38: 27.459 | G38: 24.807 | H38: -55.521 | I38: =I17 -> -55.521 | J38: =J17 -> -55.521 | K38: =K17 -> -55.521 | L38: =L17 -> -55.521 | M38: =M17 -> -55.521 | N38: =N17 -> -55.521 | O38: =O17 -> -55.521 | P38: =P17 -> -55.521 | ... R38: =R17 -> -55.521
B39: Share of associates (NCP) | D39: 0 | E39: 0 | F39: 0 | G39: -54.144 | H39: -40.284 | I39: =I18 -> -40.284 | J39: =J18 -> -40.284 | K39: =K18 -> -40.284 | L39: =L18 -> -40.284 | M39: =M18 -> -40.284 | N39: =N18 -> -40.284 | O39: =O18 -> -40.284 | P39: =P18 -> -40.284 | ... R39: =R18 -> -40.284
B40: Net profit to unitholders | D40: =D37+D38+D39 -> 246.27394 | E40: =E37+E38+E39 -> 131.21374 | F40: =F37+F38+F39 -> 20.732279 | G40: =G37+G38+G39 -> 188.64397 | H40: =H37+H38+H39 -> 474.87129 | I40: =I37+I38+I39 -> 833.16758 | J40: =J37+J38+J39 -> 966.52523 | K40: =K37+K38+K39 -> 1067.7065 | ... R40: =R37+R38+R39 -> 2021.9834
B41: Units outstanding (cr) | I41: =Inputs!$C$11 -> 82.988087 | J41: =Inputs!$C$11 -> 82.988087 | K41: =Inputs!$C$11 -> 82.988087 | L41: =Inputs!$C$11 -> 82.988087 | M41: =Inputs!$C$11 -> 82.988087 | N41: =Inputs!$C$11 -> 82.988087 | O41: =Inputs!$C$11 -> 82.988087 | P41: =Inputs!$C$11 -> 82.988087 | ... R41: =Inputs!$C$11 -> 82.988087
B42: Earnings per unit (Rs) | I42: =I40/I41 -> 10.039605 | J42: =J40/J41 -> 11.646554 | K42: =K40/K41 -> 12.86578 | L42: =L40/L41 -> 14.313228 | M42: =M40/M41 -> 15.777761 | N42: =N40/N41 -> 17.321097 | O42: =O40/O41 -> 18.947197 | P42: =P40/P41 -> 20.660223 | ... R42: =R40/R41 -> 24.364742
B43: Memo: reconciliation to user's model (uses user's interest, other income and tax rates)
B44: Net profit using user's interest | I44: =(I32+I33-I19)*(1-I13)+I38+I39 -> 900.76903 | J44: =(J32+J33-J19)*(1-J13)+J38+J39 -> 945.5308 | K44: =(K32+K33-K19)*(1-K13)+K38+K39 -> 963.5525
...

Sheet WACC
B1: COST OF CAPITAL – Damodaran INR approach
B2: Risk-free rate net of sovereign default spread · ERP = mature market + country risk premium · bottom-up beta · synthetic-rating cross-check
B4: A. Cost of equity
B5: India 10-year G-sec yield | C5: 0.0723 | F5: ICR ≥ | G5: Rating | H5: Spread | I5: Trading Economics, 7-Oct-2026 (two-year high after RBI repo hike to 5.50%)
B6: India sovereign default spread (Moody's Baa3) | C6: 0.0187 | F6: -99 | G6: Ca/CC | H6: 0.13 | I6: Damodaran country risk table, 5-Jan-2026
B7: Deduct default spread from G-sec? (1 = yes, Damodaran) | C7: 1 | F7: 0.8 | G7: Caa/CCC | H7: 0.08 | I7: Damodaran: INR risk-free rate = government bond yield − default spread
B8: INR risk-free rate | C8: =C5-C6*C7 -> 0.0536 | F8: 1.25 | G8: B3/B- | H8: 0.051
B9: Mature-market equity risk premium | C9: 0.0423 | F9: 1.5 | G9: B2/B | H9: 0.042 | I9: Damodaran implied ERP, Jan-2026
B10: India country risk premium | C10: 0.0285 | F10: 1.75 | G10: B1/B+ | H10: 0.035 | I10: Damodaran, Jan-2026 (default spread x relative equity volatility)
B11: Total equity risk premium – India | C11: =C9+C10 -> 0.0708 | F11: 2 | G11: Ba2/BB | H11: 0.024 | I11: Matches Damodaran's published India ERP 7.08%
F12: 2.25 | G12: Ba1/BB+ | H12: 0.02
B13: Bottom-up beta (Damodaran global industry betas) | C13: Unlevered β | D13: Weight | F13: 2.5 | G13: Baa2/BBB | H13: 0.0156
B14: R.E.I.T. (cash-corrected) | C14: 0.36 | D14: 0.5 | F14: 3 | G14: A3/A- | H14: 0.0121 | I14: Damodaran betas page (header: data as of Jan-2026); REIT 0.35 uncorrected. Weights: judgement (REIT-heavy, plus operating/development risk)
B15: Real Estate (Operations & Services), cash-corrected | C15: 0.51 | D15: 0.25 | F15: 4.25 | G15: A2/A | H15: 0.0107
B16: Real Estate (General/Diversified), cash-corrected | C16: 0.6 | D16: 0.25 | F16: 5.5 | G16: A1/A+ | H16: 0.0092
B17: Weighted unlevered beta | C17: =SUMPRODUCT(C14:C16,D14:D16) -> 0.4575 | F17: 6.5 | G17: Aa2/AA | H17: 0.007
B18: Target debt / (debt + equity) | C18: 0.33 | F18: 8.5 | G18: Aaa/AAA | H18: 0.0059 | I18: Management target: one-third debt / two-thirds equity for acquisitions; LTV cap 35%
B19: Implied target D/E | C19: =C18/(1-C18) -> 0.49253731 | F19: Approximate Damodaran large-firm table – refresh from ratings.xls before external use
B20: Marginal tax rate (re-levering) | C20: =Inputs!$C$42 -> 0.2517
B21: Re-levered equity beta | C21: =C17*(1+(1-C20)*C19) -> 0.62611879 | I21: Hamada: βL = βU x (1 + (1 − t) x D/E)
B22: Cost of equity (1): Damodaran (INR Rf + β x ERP) | C22: =C8+C21*C11 -> 0.097929211
B23: Cost of equity (2): G-sec + β x ERP (common practitioner) | C23: =C5+C21*C11 -> 0.11662921 | I23: Includes default spread in Rf – conservative upper bound
B24: Cost of equity (3): market-implied (DPU yield + growth) | C24: =Inputs!$C$17/Inputs!$C$10+0.04 -> 0.10812652 | I24: Annualised Q1 DPU / price + 4% stable growth – cross-check only
B25: Method selected (1, 2 or 3 = average of 1 and 2) | C25: 3 | I25: Average used: conflicts between Damodaran's and practitioner Rf conventions
B26: SELECTED COST OF EQUITY | C26: =CHOOSE(C25,C22,C23,AVERAGE(C22,C23)) -> 0.10727921
B28: B. Cost of debt
B29: Reported average interest rate (Q1 FY27) | C29: 0.073 | I29: Q1 FY27 earnings: 7.3%, ~90% floating, dual AAA (CRISIL/ICRA)
B30: Selected pre-tax cost of debt (marginal) | C30: 0.075 | I30: Peers' Q1 FY27 raises: Embassy 7.46%, Mindspace 7.42%, KRT 7.2%
B31: Implied spread over G-sec | C31: =C30-C5 -> 0.0027 | I31: AAA REIT paper trades close to G-sec given dual-AAA and lease-backed cash flows
B32: After-tax cost of debt | C32: =C30*(1-C20) -> 0.0561225
B33: Interest coverage FY27E (EBIT / interest) | C33: =Fin_Proj!I60 -> 1.9673762
B34: Synthetic rating (Damodaran-style lookup) | C34: =LOOKUP(C33,F6:F18,G6:G18) -> B1/B+ | I34: Cross-check only: REIT long-dated lease cash flows justify better than interest-cover-implied rating
B35: Synthetic spread | C35: =LOOKUP(C33,F6:F18,H6:H18) -> 0.035
B36: Synthetic cost of debt (G-sec + spread) | C36: =C5+C35 -> 0.1073
B38: C. Weighted average cost of capital
B39: Market capitalisation | C39: =Inputs!$C$12 -> 27286.483
B40: Pro-forma net debt | C40: =Inputs!$C$34 -> 14060.565
B41: Current market D / (D + E) | C41: =C40/(C39+C40) -> 0.34006212 | I41: Consolidated basis, ignores minorities
B42: Target D / (D + E) applied | C42: =C18 -> 0.33
B43: Equity weight | C43: =1-C42 -> 0.67
...

Sheet DCF_FCFF
B1: FCFF DISCOUNTED CASH FLOW – enterprise value → value per unit
B2: Mid-period discounting with stub period · Gordon-growth terminal value on normalised FCFF · bridge adjusts for net debt, partners' share and the NCP JV
B3: 1. Free cash flow to firm
B4: Rs crore | C4: Unit | I4: FY27E | J4: FY28E | K4: FY29E | L4: FY30E | M4: FY31E | N4: FY32E | O4: FY33E | P4: FY34E | Q4: FY35E | R4: FY36E
B5: Year index | I5: =Fin_Proj!I5 -> 1 | J5: =Fin_Proj!J5 -> 2 | K5: =Fin_Proj!K5 -> 3 | L5: =Fin_Proj!L5 -> 4 | M5: =Fin_Proj!M5 -> 5 | N5: =Fin_Proj!N5 -> 6 | O5: =Fin_Proj!O5 -> 7 | P5: =Fin_Proj!P5 -> 8 | ... R5: =Fin_Proj!R5 -> 10
B6: EBITDA | I6: =Fin_Proj!I29 -> 2776.0209 | J6: =Fin_Proj!J29 -> 3005.6346 | K6: =Fin_Proj!K29 -> 3200.1394 | L6: =Fin_Proj!L29 -> 3360.1464 | M6: =Fin_Proj!M29 -> 3528.1537 | N6: =Fin_Proj!N29 -> 3704.5614 | O6: =Fin_Proj!O29 -> 3889.7894 | P6: =Fin_Proj!P29 -> 4084.2789 | ... R6: =Fin_Proj!R29 -> 4502.9175
B7: Depreciation & amortisation | I7: =Fin_Proj!I31 -> 580 | J7: =Fin_Proj!J31 -> 589.17722 | K7: =Fin_Proj!K31 -> 602.43319 | L7: =Fin_Proj!L31 -> 608.45752 | M7: =Fin_Proj!M31 -> 614.5421 | N7: =Fin_Proj!N31 -> 620.68752 | O7: =Fin_Proj!O31 -> 626.8944 | P7: =Fin_Proj!P31 -> 633.16334 | ... R7: =Fin_Proj!R31 -> 645.88992
B8: EBIT | I8: =I6-I7 -> 2196.0209 | J8: =J6-J7 -> 2416.4574 | K8: =K6-K7 -> 2597.7062 | L8: =L6-L7 -> 2751.6889 | M8: =M6-M7 -> 2913.6116 | N8: =N6-N7 -> 3083.8739 | O8: =O6-O7 -> 3262.8951 | P8: =P6-P7 -> 3451.1156 | ... R8: =R6-R7 -> 3857.0276
B9: Tax rate on EBIT (P&L effective rate) | I9: =Fin_Proj!I13 -> 0.24 | J9: =Fin_Proj!J13 -> 0.25 | K9: =Fin_Proj!K13 -> 0.26 | L9: =Fin_Proj!L13 -> 0.2517 | M9: =Fin_Proj!M13 -> 0.2517 | N9: =Fin_Proj!N13 -> 0.2517 | O9: =Fin_Proj!O13 -> 0.2517 | P9: =Fin_Proj!P13 -> 0.2517 | ... R9: =Fin_Proj!R13 -> 0.2517
B10: Tax on EBIT | I10: =I8*I9 -> 527.04501 | J10: =J8*J9 -> 604.11436 | K10: =K8*K9 -> 675.40362 | L10: =L8*L9 -> 692.60008 | M10: =M8*M9 -> 733.35604 | N10: =N8*N9 -> 776.21105 | O10: =O8*O9 -> 821.27068 | P10: =P8*P9 -> 868.64579 | ... R10: =R8*R9 -> 970.81384
B11: NOPAT | I11: =I8-I10 -> 1668.9759 | J11: =J8-J10 -> 1812.3431 | K11: =K8-K10 -> 1922.3026 | L11: =L8-L10 -> 2059.0888 | M11: =M8-M10 -> 2180.2556 | N11: =N8-N10 -> 2307.6628 | O11: =O8-O10 -> 2441.6244 | P11: =P8-P10 -> 2582.4698 | ... R11: =R8-R10 -> 2886.2137
B12: + Depreciation & amortisation | I12: =I7 -> 580 | J12: =J7 -> 589.17722 | K12: =K7 -> 602.43319 | L12: =L7 -> 608.45752 | M12: =M7 -> 614.5421 | N12: =N7 -> 620.68752 | O12: =O7 -> 626.8944 | P12: =P7 -> 633.16334 | ... R12: =R7 -> 645.88992
B13: − Maintenance capex | I13: =-Fin_Proj!I65 -> -68.256 | J13: =-Fin_Proj!J65 -> -72.45612 | K13: =-Fin_Proj!K65 -> -77.420204 | L13: =-Fin_Proj!L65 -> -80.904114 | M13: =-Fin_Proj!M65 -> -84.544799 | N13: =-Fin_Proj!N65 -> -88.349315 | O13: =-Fin_Proj!O65 -> -92.325034 | P13: =-Fin_Proj!P65 -> -96.47966 | ... R13: =-Fin_Proj!R65 -> -105.3582
B14: − Growth capex (committed additions) | I14: =-Fin_Proj!I66 -> -146.25 | J14: =-Fin_Proj!J66 -> -357.5 | K14: =-Fin_Proj!K66 -> -211.25 | L14: =-Fin_Proj!L66 -> 0 | M14: =-Fin_Proj!M66 -> 0 | N14: =-Fin_Proj!N66 -> 0 | O14: =-Fin_Proj!O66 -> 0 | P14: =-Fin_Proj!P66 -> 0 | ... R14: =-Fin_Proj!R66 -> 0
B15: − Refurbishment capex | I15: =-Fin_Proj!I67 -> -150 | J15: =-Fin_Proj!J67 -> -150 | K15: =-Fin_Proj!K67 -> -150 | L15: =-Fin_Proj!L67 -> -100 | M15: =-Fin_Proj!M67 -> -100 | N15: =-Fin_Proj!N67 -> -100 | O15: =-Fin_Proj!O67 -> -100 | P15: =-Fin_Proj!P67 -> -100 | ... R15: =-Fin_Proj!R67 -> -100
B16: − Increase in net working capital | I16: =-Fin_Proj!I70 -> 48.724076 | J16: =-Fin_Proj!J70 -> 10.344606 | K16: =-Fin_Proj!K70 -> 10.427874 | L16: =-Fin_Proj!L70 -> 10.880475 | M16: =-Fin_Proj!M70 -> 11.424499 | N16: =-Fin_Proj!N70 -> 11.995724 | O16: =-Fin_Proj!O70 -> 12.59551 | P16: =-Fin_Proj!P70 -> 13.225286 | ... R16: =-Fin_Proj!R70 -> 14.580877
B17: Free cash flow to firm (FCFF) | I17: =SUM(I11:I16) -> 1933.1939 | J17: =SUM(J11:J16) -> 1831.9088 | K17: =SUM(K11:K16) -> 2096.4935 | L17: =SUM(L11:L16) -> 2497.5227 | M17: =SUM(M11:M16) -> 2621.6774 | N17: =SUM(N11:N16) -> 2751.9967 | O17: =SUM(O11:O16) -> 2888.7892 | P17: =SUM(P11:P16) -> 3032.3788 | ... R17: =SUM(R11:R16) -> 3341.3263
B18: Fraction of year after valuation date | I18: =IF(I5=1,Inputs!$C$9,1) -> 0.47123288 | J18: =IF(J5=1,Inputs!$C$9,1) -> 1 | K18: =IF(K5=1,Inputs!$C$9,1) -> 1 | L18: =IF(L5=1,Inputs!$C$9,1) -> 1 | M18: =IF(M5=1,Inputs!$C$9,1) -> 1 | N18: =IF(N5=1,Inputs!$C$9,1) -> 1 | O18: =IF(O5=1,Inputs!$C$9,1) -> 1 | P18: =IF(P5=1,Inputs!$C$9,1) -> 1 | ... R18: =IF(R5=1,Inputs!$C$9,1) -> 1
B19: FCFF counted in valuation | I19: =I17*I18 -> 910.98454 | J19: =J17*J18 -> 1831.9088 | K19: =K17*K18 -> 2096.4935 | L19: =L17*L18 -> 2497.5227 | M19: =M17*M18 -> 2621.6774 | N19: =N17*N18 -> 2751.9967 | O19: =O17*O18 -> 2888.7892 | P19: =P17*P18 -> 3032.3788 | ... R19: =R17*R18 -> 3341.3263
B20: Discount period (years, mid-period) | I20: =IF(I5=1,Inputs!$C$9/2,Inputs!$C$9+I5-1.5) -> 0.23561644 | J20: =IF(J5=1,Inputs!$C$9/2,Inputs!$C$9+J5-1.5) -> 0.97123288 | K20: =IF(K5=1,Inputs!$C$9/2,Inputs!$C$9+K5-1.5) -> 1.9712329 | L20: =IF(L5=1,Inputs!$C$9/2,Inputs!$C$9+L5-1.5) -> 2.9712329 | M20: =IF(M5=1,Inputs!$C$9/2,Inputs!$C$9+M5-1.5) -> 3.9712329 | N20: =IF(N5=1,Inputs!$C$9/2,Inputs!$C$9+N5-1.5) -> 4.9712329 | O20: =IF(O5=1,Inputs!$C$9/2,Inputs!$C$9+O5-1.5) -> 5.9712329 | P20: =IF(P5=1,Inputs!$C$9/2,Inputs!$C$9+P5-1.5) -> 6.9712329 | ... R20: =IF(R5=1,Inputs!$C$9/2,Inputs!$C$9+R5-1.5) -> 8.9712329
B21: Discount factor at WACC | I21: =1/(1+$C$25)^I20 -> 0.9798157 | J21: =1/(1+$C$25)^J20 -> 0.91938277 | K21: =1/(1+$C$25)^K20 -> 0.84316295 | L21: =1/(1+$C$25)^L20 -> 0.773262 | M21: =1/(1+$C$25)^M20 -> 0.70915607 | N21: =1/(1+$C$25)^N20 -> 0.65036473 | O21: =1/(1+$C$25)^O20 -> 0.59644738 | P21: =1/(1+$C$25)^P20 -> 0.54699995 | ... R21: =1/(1+$C$25)^R20 -> 0.46006331
